Workbook

Sheet Οδηγίες
A1: Συστηματική βιβλιογραφική ανασκόπηση: αρχείο προτύπων
A3: Σκοπός | B3: Προαιρετικό εργαλείο για τη δική σας ανασκόπηση. Ένα φύλλο για κάθε βήμα της ανασκόπησης. Ό,τι καταγράφετε εδώ μεταφέρεται στη Μεθοδολογία και στα Αποτελέσματα της εργασίας.
A4: Πού γράφετε | B4: Μόνο στα κελιά με κίτρινο φόντο. Τα λευκά κελιά περιέχουν τύπους και υπολογίζονται αυτόματα.
A5: Γραμμές παραδείγματος | B5: Οι γκρίζες γραμμές με πλάγια γράμματα είναι παραδείγματα. Διαγράψτε το περιεχόμενό τους πριν ξεκινήσετε: αλλιώς προσμετρώνται στους αριθμούς του PRISMA. Οι γραμμές παραδείγματος δείχνουν πώς συμπληρώνεται κάθε στήλη, και δεν αποτελούν μία ενιαία ανασκόπηση.
A6: 0_Συμβολοσειρά | B6: Κατασκευή της συμβολοσειράς αναζήτησης από τις έννοιες του ερωτήματός σας. Γράφετε συνώνυμα, ένα ανά κελί — η συμβολοσειρά συντίθεται αυτόματα για Scopus, ERIC και σε γενική μορφή. Την αντιγράφετε στη βάση και, όπως εκτελέστηκε, στο φύλλο 1_Αναζήτηση.
A7: 1_Αναζήτηση | B7: Ημερολόγιο αναζήτησης. Μία γραμμή για κάθε αναζήτηση σε κάθε βάση δεδομένων, με τη συμβολοσειρά ακριβώς όπως εκτελέστηκε.
A8: 2_Επιλογή | B8: Μία γραμμή για κάθε εγγραφή που εντοπίστηκε. Σε δυάδα, τα δύο μέλη αποφασίζουν ανεξάρτητα στο Στάδιο 1 (τίτλος και περίληψη) και η στήλη «Συμφωνία» δείχνει πού χρειάζεται συζήτηση. Όποιος εργάζεται ατομικά αφήνει κενή τη στήλη «Μέλος Β». Το φύλλο δέχεται έως 2.000 εγγραφές.
A9: PRISMA_αριθμοί | B9: Υπολογίζει αυτόματα τους αριθμούς του διαγράμματος ροής PRISMA 2020 από το φύλλο 2_Επιλογή και ελέγχει ότι αθροίζονται.
A10: 3_Εξαγωγή | B10: Πίνακας εξαγωγής δεδομένων. Μία γραμμή ανά μελέτη που εντάχθηκε. Οι στήλες ακολουθούν τις τέσσερις ερωτήσεις του μαθήματος: Τι, Ποιος, Γιατί, Πώς.
A11: 4_Ποιότητα | B11: Πέντε ερωτήσεις αξιολόγησης ανά μελέτη, με απάντηση ΝΑΙ, ΕΝ ΜΕΡΕΙ ή ΟΧΙ. Ο βαθμός (0 έως 5) υπολογίζεται αυτόματα: ΝΑΙ = 1, ΕΝ ΜΕΡΕΙ = 0,5, ΟΧΙ = 0.
A12: 5_Σύνθεση | B12: Μία γραμμή ανά ισχυρισμό, ομαδοποιημένες ανά ερευνητικό ερώτημα: ποιες μελέτες τον στηρίζουν, ποιες τον αντικρούουν, με ποια ποιότητα, και η πρόταση όπως θα γραφτεί στα Αποτελέσματα.
A13: Πηγές | B13: Διάγραμμα ροής και κατάλογος ελέγχου: Page et al. (2021), The PRISMA 2020 statement, BMJ. Για πληρέστερη αξιολόγηση ποιότητας: Hong et al. (2018), Mixed Methods Appraisal Tool (MMAT).

Sheet 0_Συμβολοσειρά
A1: Κατασκευή συμβολοσειράς αναζήτησης
A2: Μία στήλη ανά έννοια του ερωτήματός σας (PCC ή PICO), ένα συνώνυμο ανά κελί. Μέσα στη στήλη οι όροι ενώνονται με OR, οι στήλες μεταξύ τους με AND. Οι φράσεις μπαίνουν αυτόματα σε ευθέα εισαγωγικά.
A3: Η δική σας συμβολοσειρά: γράφετε μόνο στα κίτρινα κελιά. Αντιγράψτε το αποτέλεσμα στη βάση δεδομένων και, όπως ακριβώς εκτελέστηκε, στο φύλλο 1_Αναζήτηση.
B4: Έννοια 1 | C4: Έννοια 2 | D4: Έννοια 3 | E4: Έννοια 4 | F4: Έννοια 5
A5: Όνομα έννοιας (για εσάς)
A6: Όρος 1
A7: Όρος 2
A8: Όρος 3
A9: Όρος 4
A10: Όρος 5
A11: Όρος 6
A12: Όρος 7
A13: Όρος 8
A14: Μπλοκ (συντίθεται αυτόματα) | B14: =IF(B229="","","("&B229&")") | C14: =IF(C229="","","("&C229&")") | D14: =IF(D229="","","("&D229&")") | E14: =IF(E229="","","("&E229&")") | F14: =IF(F229="","","("&F229&")")
A16: Από έτος δημοσίευσης (π.χ. 2019)
A17: Γλώσσα, μόνο Scopus (π.χ. english)
A19: Scopus (Advanced search) | B19: =IF(F232="","","TITLE-ABS-KEY("&F232&")"&IF(B16="",""," AND PUBYEAR > "&(B16-1))&IF(B17="",""," AND LANGUAGE("&B17&")"))
A20: ERIC (eric.ed.gov) | B20: =IF(F232="","",F232&IF(B16="",""," pubyearmin:"&B16))
A21: Γενική μορφή (IEEE Xplore, ACM Digital Library) | B21: =IF(F232="","",F232)
A22: Έλεγχοι | B22: =IF(F232="","","Αστερίσκοι: "&SUMPRODUCT(LEN(B6:F13)-LEN(SUBSTITUTE(B6:F13,"*","")))&" (το IEEE Xplore δέχεται έως 10 ανά αναζήτηση). "&IF(SUMPRODUCT(--ISNUMBER(FIND("*",B6:F13)),--((ISNUMBER(FIND(" ",TRIM(B6:F13)))+ISNUMBER(FIND("-",B6:F13)))>0))>0,"ΠΡΟΣΟΧΗ: "&SUMPRODUCT(--ISNUMBER(FIND("*",B6:F13)),--((ISNUMBER(FIND(" ",TRIM(B6:F13)))+ISNUMBER(FIND("-",B6:F13)))>0))&" όρος ή όροι έχουν αστερίσκο μέσα σε φράση ή μετά από ενωτικό. Στο ERIC δεν επιστρέφουν αποτελέσματα: γράψτε τις παραλλαγές ολόκληρες.","Κανένας αστερίσκος μέσα σε φράση ή μετά από ενωτικό."))
A24: Παράδειγμα (πίνακες πληροφοριών για φοιτητές και αυτορρύθμιση στην ανώτατη εκπαίδευση). Δεν χρειάζεται να το σβήσετε: δεν επηρεάζει τη δική σας συμβολοσειρά.
B25: Έννοια 1 | C25: Έννοια 2 | D25: Έννοια 3 | E25: Έννοια 4 | F25: Έννοια 5
A26: Όνομα έννοιας (για εσάς) | B26: learning analytics | C26: πίνακες πληροφοριών | D26: αυτορρύθμιση | E26: ανώτατη εκπαίδευση
A27: Όρος 1 | B27: learning analytics | C27: dashboard* | D27: self-regulated learning | E27: higher education
A28: Όρος 2 | C28: visual analytics | D28: self-regulation | E28: universit*
A29: Όρος 3 | D29: SRL | E29: undergraduate*
A30: Όρος 4
A31: Όρος 5
A32: Όρος 6
A33: Όρος 7
A34: Όρος 8
A35: Μπλοκ (συντίθεται αυτόματα) | B35: =IF(B292="","","("&B292&")") | C35: =IF(C292="","","("&C292&")") | D35: =IF(D292="","","("&D292&")") | E35: =IF(E292="","","("&E292&")") | F35: =IF(F292="","","("&F292&")")
A37: Από έτος δημοσίευσης (π.χ. 2019) | B37: 2019
A38: Γλώσσα, μόνο Scopus (π.χ. english) | B38: english
A40: Scopus (Advanced search) | B40: =IF(F295="","","TITLE-ABS-KEY("&F295&")"&IF(B37="",""," AND PUBYEAR > "&(B37-1))&IF(B38="",""," AND LANGUAGE("&B38&")"))
A41: ERIC (eric.ed.gov) | B41: =IF(F295="","",F295&IF(B37="",""," pubyearmin:"&B37))
A42: Γενική μορφή (IEEE Xplore, ACM Digital Library) | B42: =IF(F295="","",F295)
A43: Έλεγχοι | B43: =IF(F295="","","Αστερίσκοι: "&SUMPRODUCT(LEN(B27:F34)-LEN(SUBSTITUTE(B27:F34,"*","")))&" (το IEEE Xplore δέχεται έως 10 ανά αναζήτηση). "&IF(SUMPRODUCT(--ISNUMBER(FIND("*",B27:F34)),--((ISNUMBER(FIND(" ",TRIM(B27:F34)))+ISNUMBER(FIND("-",B27:F34)))>0))>0,"ΠΡΟΣΟΧΗ: "&SUMPRODUCT(--ISNUMBER(FIND("*",B27:F34)),--((ISNUMBER(FIND(" ",TRIM(B27:F34)))+ISNUMBER(FIND("-",B27:F34)))>0))&" όρος ή όροι έχουν αστερίσκο μέσα σε φράση ή μετά από ενωτικό. Στο ERIC δεν επιστρέφουν αποτελέσματα: γράψτε τις παραλλαγές ολόκληρες.","Κανένας αστερίσκος μέσα σε φράση ή μετά από ενωτικό."))
A46: Πριν εκτελέσετε: (1) Ταιριάζει η συμβολοσειρά με το ερώτημά σας; (2) OR μέσα στο μπλοκ, AND ανάμεσα στα μπλοκ, παρενθέσεις παντού; (3) Ορθογραφία, αστερίσκοι, ευθέα εισαγωγικά; (4) Είναι τα φίλτρα αιτιολογημένα και το πλήθος εύλογο;
A47: Οι τέσσερις έλεγχοι είναι προσαρμογή του PRESS 2015 (McGowan et al., 2016, Journal of Clinical Epidemiology, 75, 40–46). Τι καταγράφεται για κάθε αναζήτηση: PRISMA-S (Rethlefsen et al., 2021, Systematic Reviews, 10, 39).
...

Sheet 1_Αναζήτηση
A1: Ημερολόγιο αναζήτησης
A2: Μία γραμμή ανά αναζήτηση. Αντιγράψτε τη συμβολοσειρά όπως ακριβώς εκτελέστηκε στη βάση. Στη στήλη «Τελική;» γράψτε ΝΑΙ μόνο στην τελική αναζήτηση κάθε βάσης: μόνο αυτές αθροίζονται στο PRISMA.
A4: Α/Α | B4: Βάση δεδομένων | C4: Ημερομηνία αναζήτησης | D4: Συμβολοσειρά αναζήτησης (όπως εκτελέστηκε) | E4: Φίλτρα | F4: Αποτελέσματα (n) | G4: Σημειώσεις | H4: Τελική; (ΝΑΙ/ΟΧΙ)
A5: 1 | B5: Scopus | C5: 2026-12-10 | D5: TITLE-ABS-KEY(("learning analytics") AND (dashboard* OR "visual analytics") AND ("self-regulat*" OR SRL) AND ("higher education" OR universit* OR undergraduate*)) AND PUBYEAR > 2018 AND LANGUAGE(english) | E5: έτος 2019 και μετά, αγγλικά, άρθρα και συνέδρια | F5: 230 | G5: Παράδειγμα: διαγράψτε το πριν ξεκινήσετε. | H5: ΝΑΙ
E27: Σύνολο εγγραφών των τελικών αναζητήσεων | F27: =SUMIF(H5:H25,"ΝΑΙ",F5:F25)

Sheet 2_Επιλογή
A1: Επιλογή μελετών σε δύο στάδια
A2: Στάδιο 1: τίτλος και περίληψη, ανεξάρτητα από τα δύο μέλη της δυάδας (ατομικά, μόνο η στήλη «Μέλος Α»). Στάδιο 2: πλήρες κείμενο. Κάθε αποκλεισμός στο Στάδιο 2 χρειάζεται λόγο. Στην τελική απόφαση του Σταδίου 1, το ΙΣΩΣ γράφεται ΝΑΙ: η εγγραφή περνά στο πλήρες κείμενο.
A4: ID | B4: Συγγραφείς | C4: Έτος | D4: Τίτλος | E4: Βάση δεδομένων | F4: Διπλοεγγραφή; | G4: Στάδιο 1: Μέλος Α | H4: Στάδιο 1: Μέλος Β | I4: Συμφωνία; | J4: Στάδιο 1: τελική απόφαση | K4: Πλήρες κείμενο βρέθηκε; | L4: Στάδιο 2: τελική απόφαση | M4: Λόγος αποκλεισμού (Στάδιο 2)
A5: 1 | B5: Herodotou, C., Rienties, B., Boroowa, A., Zdrahal, Z., & Hlosta, M. | C5: 2019 | D5: A large-scale implementation of predictive learning analytics in higher education: the teachers' role and perspective | E5: Scopus | F5: ΟΧΙ | G5: ΝΑΙ | H5: ΝΑΙ | I5: =IF(OR(G5="",H5=""),"",IF(G5=H5,"ΝΑΙ","ΣΥΖΗΤΗΣΗ")) | J5: ΝΑΙ | K5: ΝΑΙ | L5: ΕΝΤΑΞΗ
A6: 2 | B6: Herodotou, C., Rienties, B., Boroowa, A., Zdrahal, Z., & Hlosta, M. | C6: 2019 | D6: A large-scale implementation of predictive learning analytics in higher education: the teachers' role and perspective | E6: ERIC | F6: ΝΑΙ | I6: =IF(OR(G6="",H6=""),"",IF(G6=H6,"ΝΑΙ","ΣΥΖΗΤΗΣΗ"))
A7: 3 | B7: Kaliisa, R., Misiejuk, K., López-Pernas, S., Khalil, M., & Saqr, M. | C7: 2024 | D7: Have learning analytics dashboards lived up to the hype? A systematic review of impact on students' achievement, motivation, participation and attitude | E7: ACM Digital Library | F7: ΟΧΙ | G7: ΝΑΙ | H7: ΟΧΙ | I7: =IF(OR(G7="",H7=""),"",IF(G7=H7,"ΝΑΙ","ΣΥΖΗΤΗΣΗ")) | J7: ΝΑΙ | K7: ΝΑΙ | L7: ΑΠΟΚΛΕΙΣΜΟΣ | M7: Ανασκόπηση
I8: =IF(OR(G8="",H8=""),"",IF(G8=H8,"ΝΑΙ","ΣΥΖΗΤΗΣΗ"))
I9: =IF(OR(G9="",H9=""),"",IF(G9=H9,"ΝΑΙ","ΣΥΖΗΤΗΣΗ"))
I10: =IF(OR(G10="",H10=""),"",IF(G10=H10,"ΝΑΙ","ΣΥΖΗΤΗΣΗ"))
I11: =IF(OR(G11="",H11=""),"",IF(G11=H11,"ΝΑΙ","ΣΥΖΗΤΗΣΗ"))
I12: =IF(OR(G12="",H12=""),"",IF(G12=H12,"ΝΑΙ","ΣΥΖΗΤΗΣΗ"))
I13: =IF(OR(G13="",H13=""),"",IF(G13=H13,"ΝΑΙ","ΣΥΖΗΤΗΣΗ"))
I14: =IF(OR(G14="",H14=""),"",IF(G14=H14,"ΝΑΙ","ΣΥΖΗΤΗΣΗ"))
I15: =IF(OR(G15="",H15=""),"",IF(G15=H15,"ΝΑΙ","ΣΥΖΗΤΗΣΗ"))
I16: =IF(OR(G16="",H16=""),"",IF(G16=H16,"ΝΑΙ","ΣΥΖΗΤΗΣΗ"))
I17: =IF(OR(G17="",H17=""),"",IF(G17=H17,"ΝΑΙ","ΣΥΖΗΤΗΣΗ"))
I18: =IF(OR(G18="",H18=""),"",IF(G18=H18,"ΝΑΙ","ΣΥΖΗΤΗΣΗ"))
I19: =IF(OR(G19="",H19=""),"",IF(G19=H19,"ΝΑΙ","ΣΥΖΗΤΗΣΗ"))
... I2004: =IF(OR(G2004="",H2004=""),"",IF(G2004=H2004,"ΝΑΙ","ΣΥΖΗΤΗΣΗ"))

Sheet PRISMA_αριθμοί
A1: Αριθμοί για το διάγραμμα ροής PRISMA 2020
A2: Υπολογίζονται αυτόματα από το φύλλο 2_Επιλογή. Μην γράφετε σε αυτό το φύλλο.
A4: Φάση | B4: Μέγεθος | C4: n | D4: Έλεγχος
A5: Εντοπισμός | B5: Εγγραφές που εντοπίστηκαν (γραμμές στο φύλλο 2_Επιλογή) | C5: =COUNTA('2_Επιλογή'!B5:B2004) | D5: =IF(C5='1_Αναζήτηση'!F27,"Συμφωνεί με το ημερολόγιο αναζήτησης","Διαφέρει από το ημερολόγιο: ελέγξτε ότι καταχωρίσατε όλες τις εγγραφές")
B6: Αφαιρέθηκαν πριν από τον έλεγχο: διπλοεγγραφές | C6: =COUNTIF('2_Επιλογή'!F5:F2004,"ΝΑΙ")
A7: Έλεγχος | B7: Εγγραφές που ελέγχθηκαν με βάση τίτλο και περίληψη | C7: =C5-C6 | D7: =IF(C7=C8+C9,"Αθροίζει","Εκκρεμούν αποφάσεις στο Στάδιο 1")
B8: Αποκλείστηκαν στο Στάδιο 1 | C8: =COUNTIF('2_Επιλογή'!J5:J2004,"ΟΧΙ")
B9: Πλήρη κείμενα που αναζητήθηκαν | C9: =COUNTIF('2_Επιλογή'!J5:J2004,"ΝΑΙ")
B10: Πλήρη κείμενα που δεν ανακτήθηκαν | C10: =COUNTIF('2_Επιλογή'!K5:K2004,"ΟΧΙ")
B11: Πλήρη κείμενα που αξιολογήθηκαν | C11: =C9-C10 | D11: =IF(C11=C12+C13,"Αθροίζει","Εκκρεμούν αποφάσεις στο Στάδιο 2")
B12: Αποκλείστηκαν με αιτιολογία στο Στάδιο 2 | C12: =COUNTIF('2_Επιλογή'!L5:L2004,"ΑΠΟΚΛΕΙΣΜΟΣ")
A13: Ένταξη | B13: Μελέτες που εντάχθηκαν στην ανασκόπηση | C13: =COUNTIF('2_Επιλογή'!L5:L2004,"ΕΝΤΑΞΗ")
A16: Λόγοι αποκλεισμού στο Στάδιο 2
B17: Όχι εμπειρική μελέτη | C17: =COUNTIF('2_Επιλογή'!M5:M2004,B17)
B18: Εκτός πληθυσμού ή πλαισίου | C18: =COUNTIF('2_Επιλογή'!M5:M2004,B18)
B19: Εκτός έννοιας ενδιαφέροντος | C19: =COUNTIF('2_Επιλογή'!M5:M2004,B19)
B20: Ανασκόπηση | C20: =COUNTIF('2_Επιλογή'!M5:M2004,B20)
A23: Μελέτες που εντάχθηκαν, ανά έτος (από το φύλλο 3_Εξαγωγή)
B24: 2019 | C24: =COUNTIF('3_Εξαγωγή'!C5:C104,B24) | D24: Υπόθεση: χρονικό εύρος 2019 έως 2026, όπως στο παράδειγμα του μαθήματος. Αλλάξτε τα έτη στη στήλη Β αν το δικό σας εύρος διαφέρει.
B25: 2020 | C25: =COUNTIF('3_Εξαγωγή'!C5:C104,B25)
B26: 2021 | C26: =COUNTIF('3_Εξαγωγή'!C5:C104,B26)
B27: 2022 | C27: =COUNTIF('3_Εξαγωγή'!C5:C104,B27)
B28: 2023 | C28: =COUNTIF('3_Εξαγωγή'!C5:C104,B28)
B29: 2024 | C29: =COUNTIF('3_Εξαγωγή'!C5:C104,B29)
B30: 2025 | C30: =COUNTIF('3_Εξαγωγή'!C5:C104,B30)
B31: 2026 | C31: =COUNTIF('3_Εξαγωγή'!C5:C104,B31)

Sheet 3_Εξαγωγή
A1: Πίνακας εξαγωγής δεδομένων
A2: Μία γραμμή ανά μελέτη που εντάχθηκε. Ίδιες στήλες για όλες τις μελέτες. Δοκιμάστε τον πίνακα σε τρεις μελέτες πριν συνεχίσετε.
A4: ID | B4: Παραπομπή (APA 7) | C4: Έτος | D4: Χώρα | E4: Τι; Εκπαιδευτικό πλαίσιο | F4: Τι; Δεδομένα | G4: Ποιος; Ενδιαφερόμενοι | H4: Γιατί; Στόχος | I4: Πώς; Μέθοδος | J4: Δείγμα | K4: Κύρια ευρήματα | L4: Περιορισμοί | M4: Σχετικό με ΕΕ1; | N4: Σχετικό με ΕΕ2; | O4: Σχετικό με ΕΕ3;
A5: 1 | B5: Herodotou, C., Rienties, B., Boroowa, A., Zdrahal, Z., & Hlosta, M. (2019). A large-scale implementation of predictive learning analytics in higher education: the teachers' role and perspective. Educational Technology Research and Development, 67(5), 1273–1306. | C5: 2019 | D5: Ηνωμένο Βασίλειο | E5: εξ αποστάσεως πανεπιστήμιο | F5: δημογραφικά και ίχνη από το εικονικό περιβάλλον μάθησης | G5: διδάσκοντες | H5: έγκαιρος εντοπισμός φοιτητών σε κίνδυνο | I5: προγνωστικό μοντέλο και πίνακας πληροφοριών | J5: 59 διδάσκοντες σε εννέα μαθήματα, με 1.325 φοιτητές | K5: Η συχνότερη χρήση των προβλέψεων από τους διδάσκοντες συνδέθηκε με καλύτερα ποσοστά ολοκλήρωσης και επιτυχίας. | L5: Συσχέτιση, όχι αιτιότητα. | M5: ΝΑΙ | N5: ΝΑΙ | O5: ΝΑΙ

Sheet 4_Ποιότητα
A1: Αξιολόγηση ποιότητας
A2: Απαντήστε ΝΑΙ, ΕΝ ΜΕΡΕΙ ή ΟΧΙ. Ο βαθμός υπολογίζεται αυτόματα: ΝΑΙ = 1, ΕΝ ΜΕΡΕΙ = 0,5, ΟΧΙ = 0. Η αξιολόγηση δεν αποκλείει μελέτες: δείχνει πόσο βάρος δίνετε στα ευρήματά τους.
A4: ID | B4: Παραπομπή (σύντομη) | C4: 1. Σαφές ερευνητικό ερώτημα; | D4: 2. Περιγράφονται δείγμα και πλαίσιο; | E4: 3. Κατάλληλη μέθοδος; | F4: 4. Τα συμπεράσματα στηρίζονται στα δεδομένα; | G4: 5. Αναφέρονται περιορισμοί; | H4: Βαθμός (0 έως 5) | I4: Σχόλια
A5: 1 | B5: Herodotou et al. (2019) | C5: ΝΑΙ | D5: ΝΑΙ | E5: ΝΑΙ | F5: ΕΝ ΜΕΡΕΙ | G5: ΝΑΙ | H5: =IF(COUNTA(C5:G5)=0,"",COUNTIF(C5:G5,"ΝΑΙ")+0.5*COUNTIF(C5:G5,"ΕΝ ΜΕΡΕΙ")) | I5: Παράδειγμα: διαγράψτε το πριν ξεκινήσετε.
H6: =IF(COUNTA(C6:G6)=0,"",COUNTIF(C6:G6,"ΝΑΙ")+0.5*COUNTIF(C6:G6,"ΕΝ ΜΕΡΕΙ"))
H7: =IF(COUNTA(C7:G7)=0,"",COUNTIF(C7:G7,"ΝΑΙ")+0.5*COUNTIF(C7:G7,"ΕΝ ΜΕΡΕΙ"))
H8: =IF(COUNTA(C8:G8)=0,"",COUNTIF(C8:G8,"ΝΑΙ")+0.5*COUNTIF(C8:G8,"ΕΝ ΜΕΡΕΙ"))
H9: =IF(COUNTA(C9:G9)=0,"",COUNTIF(C9:G9,"ΝΑΙ")+0.5*COUNTIF(C9:G9,"ΕΝ ΜΕΡΕΙ"))
H10: =IF(COUNTA(C10:G10)=0,"",COUNTIF(C10:G10,"ΝΑΙ")+0.5*COUNTIF(C10:G10,"ΕΝ ΜΕΡΕΙ"))
H11: =IF(COUNTA(C11:G11)=0,"",COUNTIF(C11:G11,"ΝΑΙ")+0.5*COUNTIF(C11:G11,"ΕΝ ΜΕΡΕΙ"))
H12: =IF(COUNTA(C12:G12)=0,"",COUNTIF(C12:G12,"ΝΑΙ")+0.5*COUNTIF(C12:G12,"ΕΝ ΜΕΡΕΙ"))
H13: =IF(COUNTA(C13:G13)=0,"",COUNTIF(C13:G13,"ΝΑΙ")+0.5*COUNTIF(C13:G13,"ΕΝ ΜΕΡΕΙ"))
H14: =IF(COUNTA(C14:G14)=0,"",COUNTIF(C14:G14,"ΝΑΙ")+0.5*COUNTIF(C14:G14,"ΕΝ ΜΕΡΕΙ"))
H15: =IF(COUNTA(C15:G15)=0,"",COUNTIF(C15:G15,"ΝΑΙ")+0.5*COUNTIF(C15:G15,"ΕΝ ΜΕΡΕΙ"))
H16: =IF(COUNTA(C16:G16)=0,"",COUNTIF(C16:G16,"ΝΑΙ")+0.5*COUNTIF(C16:G16,"ΕΝ ΜΕΡΕΙ"))
H17: =IF(COUNTA(C17:G17)=0,"",COUNTIF(C17:G17,"ΝΑΙ")+0.5*COUNTIF(C17:G17,"ΕΝ ΜΕΡΕΙ"))
... H104: =IF(COUNTA(C104:G104)=0,"",COUNTIF(C104:G104,"ΝΑΙ")+0.5*COUNTIF(C104:G104,"ΕΝ ΜΕΡΕΙ"))

Sheet 5_Σύνθεση
A1: Σύνθεση των ευρημάτων
A2: Μία γραμμή ανά ισχυρισμό. Κάθε ερευνητικό ερώτημα γίνεται μία ενότητα στα Αποτελέσματα, και κάθε γραμμή μία πρόταση της ενότητας. Χωρίς ερμηνεία: η ερμηνεία ανήκει στη Συζήτηση.
A4: ΕΕ | B4: Ισχυρισμός (μία πρόταση, χωρίς ερμηνεία) | C4: Μελέτες υπέρ (ID από το φύλλο 3, χωρισμένα με ;) | D4: Μελέτες κατά ή με επιφύλαξη (ID, με ;) | E4: Πλήθος υπέρ | F4: Πλήθος κατά | G4: Ποιότητα των μελετών υπέρ (μέσος βαθμός, φύλλο 4) | H4: Σε ποια πλαίσια ισχύει | I4: Η πρόταση όπως θα γραφτεί στα Αποτελέσματα
A5: ΕΕ1 | B5: Η συχνότερη χρήση των προβλέψεων από τους διδάσκοντες συνδέεται με καλύτερα ποσοστά επιτυχίας. | C5: 1 | E5: =IF(TRIM(C5)="","",LEN(TRIM(C5))-LEN(SUBSTITUTE(TRIM(C5),";",""))+1) | F5: =IF(TRIM(D5)="","",LEN(TRIM(D5))-LEN(SUBSTITUTE(TRIM(D5),";",""))+1) | G5: 4.5 | H5: εξ αποστάσεως πανεπιστήμιο, Ηνωμένο Βασίλειο | I5: Παράδειγμα: ισχυρισμός που στηρίζεται σε μία μόνο μελέτη διατυπώνεται ως ένδειξη, όχι ως εύρημα. Διαγράψτε τη γραμμή πριν ξεκινήσετε.
E6: =IF(TRIM(C6)="","",LEN(TRIM(C6))-LEN(SUBSTITUTE(TRIM(C6),";",""))+1) | F6: =IF(TRIM(D6)="","",LEN(TRIM(D6))-LEN(SUBSTITUTE(TRIM(D6),";",""))+1)
E7: =IF(TRIM(C7)="","",LEN(TRIM(C7))-LEN(SUBSTITUTE(TRIM(C7),";",""))+1) | F7: =IF(TRIM(D7)="","",LEN(TRIM(D7))-LEN(SUBSTITUTE(TRIM(D7),";",""))+1)
E8: =IF(TRIM(C8)="","",LEN(TRIM(C8))-LEN(SUBSTITUTE(TRIM(C8),";",""))+1) | F8: =IF(TRIM(D8)="","",LEN(TRIM(D8))-LEN(SUBSTITUTE(TRIM(D8),";",""))+1)
E9: =IF(TRIM(C9)="","",LEN(TRIM(C9))-LEN(SUBSTITUTE(TRIM(C9),";",""))+1) | F9: =IF(TRIM(D9)="","",LEN(TRIM(D9))-LEN(SUBSTITUTE(TRIM(D9),";",""))+1)
E10: =IF(TRIM(C10)="","",LEN(TRIM(C10))-LEN(SUBSTITUTE(TRIM(C10),";",""))+1) | F10: =IF(TRIM(D10)="","",LEN(TRIM(D10))-LEN(SUBSTITUTE(TRIM(D10),";",""))+1)
E11: =IF(TRIM(C11)="","",LEN(TRIM(C11))-LEN(SUBSTITUTE(TRIM(C11),";",""))+1) | F11: =IF(TRIM(D11)="","",LEN(TRIM(D11))-LEN(SUBSTITUTE(TRIM(D11),";",""))+1)
E12: =IF(TRIM(C12)="","",LEN(TRIM(C12))-LEN(SUBSTITUTE(TRIM(C12),";",""))+1) | F12: =IF(TRIM(D12)="","",LEN(TRIM(D12))-LEN(SUBSTITUTE(TRIM(D12),";",""))+1)
E13: =IF(TRIM(C13)="","",LEN(TRIM(C13))-LEN(SUBSTITUTE(TRIM(C13),";",""))+1) | F13: =IF(TRIM(D13)="","",LEN(TRIM(D13))-LEN(SUBSTITUTE(TRIM(D13),";",""))+1)
E14: =IF(TRIM(C14)="","",LEN(TRIM(C14))-LEN(SUBSTITUTE(TRIM(C14),";",""))+1) | F14: =IF(TRIM(D14)="","",LEN(TRIM(D14))-LEN(SUBSTITUTE(TRIM(D14),";",""))+1)
E15: =IF(TRIM(C15)="","",LEN(TRIM(C15))-LEN(SUBSTITUTE(TRIM(C15),";",""))+1) | F15: =IF(TRIM(D15)="","",LEN(TRIM(D15))-LEN(SUBSTITUTE(TRIM(D15),";",""))+1)
E16: =IF(TRIM(C16)="","",LEN(TRIM(C16))-LEN(SUBSTITUTE(TRIM(C16),";",""))+1) | F16: =IF(TRIM(D16)="","",LEN(TRIM(D16))-LEN(SUBSTITUTE(TRIM(D16),";",""))+1)
E17: =IF(TRIM(C17)="","",LEN(TRIM(C17))-LEN(SUBSTITUTE(TRIM(C17),";",""))+1) | F17: =IF(TRIM(D17)="","",LEN(TRIM(D17))-LEN(SUBSTITUTE(TRIM(D17),";",""))+1)
... E64: =IF(TRIM(C64)="","",LEN(TRIM(C64))-LEN(SUBSTITUTE(TRIM(C64),";",""))+1) | F64: =IF(TRIM(D64)="","",LEN(TRIM(D64))-LEN(SUBSTITUTE(TRIM(D64),";",""))+1)
